<?xml version='1.0'?>
<robot name="AllegroHand">

    <link name="ground">
      <inertial>
        <origin xyz="0 0 0.05" rpy="0 0 0" />
        <mass value="4" />
        <inertia ixx="0.4" iyy="0.4" izz="0.4" ixy="0" ixz="0" iyz="0" />
      </inertial>
    </link>


    <link name="virtual_link_1">
      <inertial>
        <origin xyz="0 0 0" rpy="0 0 0" />
        <mass value="0.0001" />
        <inertia ixx="0.0001" iyy="0.0001" izz="0.0001" ixy="0" ixz="0" iyz="0" />
      </inertial>
    </link>
    <link name="virtual_link_2">
      <inertial>
        <origin xyz="0 0 0" rpy="0 0 0" />
        <mass value="0.0001" />
        <inertia ixx="0.0001" iyy="0.0001" izz="0.0001" ixy="0" ixz="0" iyz="0" />
      </inertial>
    </link>
    <link name="virtual_link_3">
      <inertial>
        <origin xyz="0 0 0" rpy="0 0 0" />
        <mass value="0.0001" />
        <inertia ixx="0.0001" iyy="0.0001" izz="0.0001" ixy="0" ixz="0" iyz="0" />
      </inertial>
    </link>
    <link name="virtual_link_4">
      <inertial>
        <origin xyz="0 0 0" rpy="0 0 0" />
        <mass value="0.0001" />
        <inertia ixx="0.0001" iyy="0.0001" izz="0.0001" ixy="0" ixz="0" iyz="0" />
      </inertial>
    </link>
    <link name="virtual_link_5">
      <inertial>
        <origin xyz="0 0 0" rpy="0 0 0" />
        <mass value="0.0001" />
        <inertia ixx="0.0001" iyy="0.0001" izz="0.0001" ixy="0" ixz="0" iyz="0" />
      </inertial>
    </link>
    <link name="virtual_link_6">
      <inertial>
        <origin xyz="0 0 0" rpy="0 0 0" />
        <mass value="0.0001" />
        <inertia ixx="0.0001" iyy="0.0001" izz="0.0001" ixy="0" ixz="0" iyz="0" />
      </inertial>
    </link>

    <joint name="virtual_px" type="prismatic">
        <axis xyz="1 0 0"/>
        <limit effort="0" lower="-100" upper="100" velocity="0"/>
        <parent link="ground"/>
        <child link="virtual_link_1"/>
        <origin rpy="0 0 0" xyz="0 0 0"/>
    </joint>
    <joint name="virtual_py" type="prismatic">
        <axis xyz="0 1 0"/>
        <limit effort="0" lower="-100" upper="100" velocity="0"/>
        <parent link="virtual_link_1"/>
        <child link="virtual_link_2"/>
        <origin rpy="0 0 0" xyz="0 0 0"/>
    </joint>
    <joint name="virtual_pz" type="prismatic">
        <axis xyz="0 0 1"/>
        <limit effort="0" lower="-100" upper="100" velocity="0"/>
        <parent link="virtual_link_2"/>
        <child link="virtual_link_3"/>
        <origin rpy="0 0 0" xyz="0 0 0"/>
    </joint>
    <joint name="virtual_ry" type="revolute">
        <axis xyz="0 1 0"/>
        <limit effort="0" lower="-100" upper="100" velocity="0"/>
        <parent link="virtual_link_3"/>
        <child link="virtual_link_4"/>
        <origin rpy="0 0 0" xyz="0 0 0"/>
    </joint>
    <joint name="virtual_rx" type="revolute">
        <axis xyz="1 0 0"/>
        <limit effort="0" lower="-100" upper="100" velocity="0"/>
        <parent link="virtual_link_4"/>
        <child link="virtual_link_5"/>
        <origin rpy="0 0 0" xyz="0 0 0"/>
    </joint>    
    <joint name="virtual_rz" type="revolute">
        <axis xyz="0 0 1"/>
        <limit effort="0" lower="-100" upper="100" velocity="0"/>
        <parent link="virtual_link_5"/>
        <child link="virtual_link_6"/>
        <origin rpy="0 0 0" xyz="0 0 0"/>
    </joint>


    <link name="palm">
        <inertial>
            <origin xyz="0.0 0.0 0.0475" rpy="0 0 0" />
            <mass value="0.4154" />
            <inertia ixx="1e-4" iyy="1e-4" izz="1e-4" ixy="0" ixz="0" iyz="0" />
        </inertial>
        <visual>
            <origin xyz="0.0 0.0 0.0" rpy="0 0 0" />
            <geometry>
                <mesh filename="../../../Model/AllegroHand/meshes/visual/base_link.obj" scale="1 1 1" />
            </geometry>
            <material name="material_red">
                <color rgba="1.0 0.1 0.1 1.0" />
            </material>
        </visual>
    </link>

    <joint name="joint_hand" type="fixed">
        <axis xyz="0 0 1"/>
        <limit effort="0" lower="-0.47" upper="0.47" velocity="0"/>
        <parent link="virtual_link_6"/>
        <child link="palm"/>
        <origin rpy="0 0 0" xyz="0 0 0"/>
    </joint>


    <link name="link_0.0">
        <inertial>
            <mass value="0.0119" />
            <origin xyz="0 0 0" rpy="0 0 0"/>
            <inertia ixx="1.01666658333e-06" ixy="0.0" ixz="0.0" iyy="6.47677333333e-07" iyz="0.0" izz=" 1.01666658333e-06" />
        </inertial>
        <visual>
            <geometry>
                <mesh filename="../../../Model/AllegroHand/meshes/visual/link_0.0.obj"/>
            </geometry>
        </visual>
        <collision>
            <!--<geometry>
                <box size="0.0196 0.0275 0.0164"/>
            </geometry>
            <origin rpy="0 0 0" xyz="0 0 0.0082"/>-->
        </collision>
    </link>  

    <joint name="joint_0.0" type="revolute">
        <axis xyz="0 0 1"/>
        <limit effort="0" lower="-0.47" upper="0.47" velocity="0"/>
        <parent link="palm"/>
        <child link="link_0.0"/>
        <origin rpy="-0.08726646255 0 0" xyz="0 0.0436512 -0.0022438"/>
    </joint>

    <link name="link_1.0">
        <inertial>
            <mass value="0.065" />
            <origin xyz="0 0 0" rpy="0 0 0"/>
            <inertia ixx="7.95654166667e-05" ixy="1.7199e-05" ixz="8.75875e-06" iyy="2.47088833333e-05" iyz="2.413125e-05" izz="7.95654166667e-05" />
        </inertial>
        <visual>
            <geometry>
                <mesh filename="../../../Model/AllegroHand/meshes/visual/link_1.0.obj"/>
            </geometry>
            <material name="green">
              <color rgba="0.3 0.5 0.2 1.0"/>
            </material>
        </visual>
        <collision>
            <!--<origin xyz="0 0 0" rpy="0 0 0" />
            <geometry>
                <mesh filename="link_1.0.obj" scale="1 1 1" />
            </geometry>-->
        </collision>
    </link>

    <joint name="joint_1.0" type="revolute">
        <limit effort="0" lower="-0.196" upper="1.61" velocity="0"/>
        <axis xyz="0 1 0"/>
        <parent link="link_0.0"/>
        <child link="link_1.0"/>
        <origin xyz="0 0 0.0166"/>
    </joint>
    
    <link name="link_2.0">
        <inertial>
            <mass value="0.0355" />
            <origin xyz="0 0 0" rpy="0 0 0"/>
            <inertia ixx="2.63979183333e-05" ixy="6.67968e-06" ixz="4.783625e-06"
                       iyy="1.34948516667e-05" iyz="9.372e-06"
                       izz="2.63979183333e-05" />
        </inertial>
        <visual>
            <geometry>
                <mesh filename="../../../Model/AllegroHand/meshes/visual/link_2.0.obj"/>
            </geometry>
            <material name="green"/>
        </visual>
        <collision>
            <!--<origin xyz="0 0 0" rpy="0 0 0" />
            <geometry>
                <mesh filename="link_2.0.obj" scale="1 1 1" />
            </geometry>-->
        </collision>
    </link>

    <joint name="joint_2.0" type="revolute">
        <axis xyz="0 1 0"/>
        <limit effort="0" lower="-0.174" upper="1.709" velocity="0"/>
        <parent link="link_1.0"/>
        <child link="link_2.0"/>
        <origin xyz="0 0 0.054"/>
    </joint>    

    <link name="link_3.0">
        <inertial>
            <mass value="0.0096" />
            <origin xyz="0 0 0" rpy="0 0 0"/>
            <inertia ixx="4.701248e-06" ixy="1.255968e-06" ixz="1.2936e-06"
                       iyy="3.649312e-06" iyz="1.7622e-06"
                       izz="4.701248e-06" />
        </inertial>
        <visual>
            <geometry>
                <mesh filename="../../../Model/AllegroHand/meshes/visual/link_3.0.obj"/>
            </geometry>
            <material name="green"/>
        </visual>
         <collision>        
        </collision> 
    </link>

    <joint name="joint_3.0" type="revolute">
        <axis xyz="0 1 0"/>
        <limit effort="0" lower="-0.227" upper="1.618" velocity="0"/>
        <parent link="link_2.0"/>
        <child link="link_3.0"/>
        <origin xyz="0 0 0.0384"/>
    </joint>


    <link name="link_3.0_tip">
        <inertial>
            <mass value="0.0096" />
            <origin xyz="0 0 0" rpy="0 0 0"/>
            <inertia ixx="4.701248e-06" ixy="1.255968e-06" ixz="1.2936e-06"
                       iyy="3.649312e-06" iyz="1.7622e-06"
                       izz="4.701248e-06" />
        </inertial>
        <visual>
            <origin xyz="0.0 0.0 0.0" rpy="0 0 0" />
            <geometry>
               <!--  <mesh filename="../../../Model/AllegroHand/meshes/visual/link_3.0_tip.obj"/> -->
               <sphere radius="0.014" />
            </geometry>
            <material name="green"/>
        </visual>
        <collision>
            <origin xyz="0 0 0.0" rpy="0 0 0" />
            <geometry>
                <!--<mesh filename="link_3.0_tip.obj" scale="1 1 1" />-->
                <sphere radius="0.014" />
            </geometry>            
        </collision>
    </link>

    <joint name="joint_3.0_tip" type="fixed">
        <parent link="link_3.0"/>
        <child link="link_3.0_tip"/>
        <origin rpy="0 0 0" xyz="0 0 0.0297"/> <!--The tip joint is in the center of the sphere, which is 0.0157+0.014 m from the joint_3.0-->
    </joint> 

    <link name="link_4.0">
        <inertial>
            <mass value="0.0119" />
            <origin xyz="0 0 0" rpy="0 0 0"/>
            <inertia ixx="1.01666658333e-06" ixy="0.0" ixz="0.0" iyy="6.47677333333e-07" iyz="0.0" izz=" 1.01666658333e-06" />
        </inertial>
        <visual>
            <geometry>
                <mesh filename="../../../Model/AllegroHand/meshes/visual/link_0.0.obj"/>
            </geometry>
            <material name="green"/>
        </visual>
        <collision>
        </collision>
    </link> 

    <joint name="joint_4.0" type="revolute">
        <axis xyz="0 0 1"/>
        <limit effort="0" lower="-0.47" upper="0.47" velocity="0"/>
        <parent link="palm"/>
        <child link="link_4.0"/>
        <origin xyz="0.0 0.0 0.0" rpy="0.0 0.0 0.0"/>
    </joint>

    <link name="link_5.0">
        <inertial>
            <mass value="0.065" />
            <origin xyz="0 0 0" rpy="0 0 0"/>
            <inertia ixx="7.95654166667e-05" ixy="1.7199e-05" ixz="8.75875e-06" iyy="2.47088833333e-05" iyz="2.413125e-05" izz="7.95654166667e-05" />
        </inertial>
        <visual>
            <geometry>
                <mesh filename="../../../Model/AllegroHand/meshes/visual/link_1.0.obj"/>
            </geometry>
            <material name="green"/>
        </visual>
        <collision>
           <!--  <origin xyz="0 0 0.0" rpy="0 0 0" />
            <geometry>
                <mesh filename="../../../Model/meshes/collision/link_1.0.obj" scale="1 1 1" />
            </geometry> -->
        </collision>
    </link>
    
    <joint name="joint_5.0" type="revolute">
        <limit effort="0" lower="-0.196" upper="1.61" velocity="0"/>
        <axis xyz="0 1 0"/>
        <parent link="link_4.0"/>
        <child link="link_5.0"/>
        <origin xyz="0 0 0.0166"/>
    </joint>
    
    <link name="link_6.0">
        <inertial>
            <mass value="0.0355" />
            <origin xyz="0 0 0" rpy="0 0 0"/>
            <inertia ixx="2.63979183333e-05" ixy="6.67968e-06" ixz="4.783625e-06"
                       iyy="1.34948516667e-05" iyz="9.372e-06"
                       izz="2.63979183333e-05" />
        </inertial>
    <visual>
        <geometry>
            <mesh filename="../../../Model/AllegroHand/meshes/visual/link_2.0.obj"/>
        </geometry>
        <material name="green"/>
    </visual>
    <collision>
      <!--  <origin xyz="0 0 0.0" rpy="0 0 0" />
            <geometry>
                <mesh filename="../../../Model/meshes/collision/link_2.0.obj" scale="1 1 1" />
            </geometry> -->
    </collision>
    </link>
    
    <joint name="joint_6.0" type="revolute">
        <axis xyz="0 1 0"/>
        <limit effort="0" lower="-0.174" upper="1.709" velocity="0"/>
        <parent link="link_5.0"/>
        <child link="link_6.0"/>
        <origin xyz="0 0 0.054"/>
    </joint>




    <link name="link_7.0">
        <inertial>
            <mass value="0.0096" />
            <origin xyz="0 0 0" rpy="0 0 0"/>
            <inertia ixx="4.701248e-06" ixy="1.255968e-06" ixz="1.2936e-06"
                       iyy="3.649312e-06" iyz="1.7622e-06"
                       izz="4.701248e-06" />
        </inertial>
        <visual>
            <geometry>
                <mesh filename="../../../Model/AllegroHand/meshes/visual/link_3.0.obj"/>
            </geometry>
            <material name="green"/>
        </visual>
         <collision>        
        </collision> 
    </link>

    <joint name="joint_7.0" type="revolute">
        <axis xyz="0 1 0"/>
        <limit effort="0" lower="-0.227" upper="1.618" velocity="0"/>
        <parent link="link_6.0"/>
        <child link="link_7.0"/>
        <origin xyz="0 0 0.0384"/>
    </joint>


    <link name="link_7.0_tip">
        <inertial>
            <mass value="0.0096" />
            <origin xyz="0 0 0" rpy="0 0 0"/>
            <inertia ixx="4.701248e-06" ixy="1.255968e-06" ixz="1.2936e-06"
                       iyy="3.649312e-06" iyz="1.7622e-06"
                       izz="4.701248e-06" />
        </inertial>
        <visual>
            <origin xyz="0.0 0.0 0.0" rpy="0 0 0" />
            <geometry>
                <!-- <mesh filename="../../../Model/AllegroHand/meshes/visual/link_3.0_tip.obj"/> -->
                <sphere radius="0.014" />
            </geometry>
            <material name="green"/>
        </visual>
        <collision>
            <origin xyz="0 0 0.0" rpy="0 0 0" />
            <geometry>
                <!--<mesh filename="link_3.0_tip.obj" scale="1 1 1" />-->
                <sphere radius="0.014" />
            </geometry>            
        </collision>
    </link>

    <joint name="joint_7.0_tip" type="fixed">
        <parent link="link_7.0"/>
        <child link="link_7.0_tip"/>
        <origin rpy="0 0 0" xyz="0 0 0.0297"/> <!--The tip joint is in the center of the sphere, which is 0.0157+0.014 m from the joint_3.0-->
    </joint> 


    <link name="link_8.0">
        <inertial>
            <mass value="0.0119" />
            <origin xyz="0 0 0" rpy="0 0 0"/>
            <inertia ixx="1.01666658333e-06" ixy="0.0" ixz="0.0" iyy="6.47677333333e-07" iyz="0.0" izz=" 1.01666658333e-06" />
        </inertial>
        <visual>
            <geometry>
                <mesh filename="../../../Model/AllegroHand/meshes/visual/link_0.0.obj"/>
            </geometry>
            <material name="green"/>
        </visual>
        <collision>
           <!-- <origin xyz="0 0 0.0" rpy="0 0 0" />
            <geometry>
                <mesh filename="../../../Model/meshes/collision/link_0.0.obj" scale="1 1 1" />
            </geometry> -->
        </collision>
    </link>
    
    <joint name="joint_8.0" type="revolute">
        <axis xyz="0 0 1"/>
        <limit effort="0" lower="-0.47" upper="0.47" velocity="0"/>
        <parent link="palm"/>
        <child link="link_8.0"/>
        <origin rpy="0.08726646255 0 0" xyz="0 -0.0436512 -0.0022438"/>
    </joint>
    
    <link name="link_9.0">
        <inertial>
            <mass value="0.065" />
            <origin xyz="0 0 0" rpy="0 0 0"/>
            <inertia ixx="7.95654166667e-05" ixy="1.7199e-05" ixz="8.75875e-06" iyy="2.47088833333e-05" iyz="2.413125e-05" izz="7.95654166667e-05" />
        </inertial>
        <visual>
            <geometry>
                <mesh filename="../../../Model/AllegroHand/meshes/visual/link_1.0.obj"/>
            </geometry>
            <material name="green"/>
        </visual>
        <collision>
           <!-- <origin xyz="0 0 0.0" rpy="0 0 0" />
            <geometry>
                <mesh filename="../../../Model/meshes/collision/link_1.0.obj" scale="1 1 1" />
            </geometry> -->
        </collision>
    </link>
    
    <joint name="joint_9.0" type="revolute">
        <limit effort="0" lower="-0.196" upper="1.61" velocity="0"/>
        <axis xyz="0 1 0"/>
        <parent link="link_8.0"/>
        <child link="link_9.0"/>
        <origin xyz="0 0 0.0166"/>
    </joint>
    
    <link name="link_10.0">
        <inertial>
            <mass value="0.0355" />
            <origin xyz="0 0 0" rpy="0 0 0"/>
            <inertia ixx="2.63979183333e-05" ixy="6.67968e-06" ixz="4.783625e-06"
                       iyy="1.34948516667e-05" iyz="9.372e-06"
                       izz="2.63979183333e-05" />
        </inertial>
        <visual>
            <geometry>
                <mesh filename="../../../Model/AllegroHand/meshes/visual/link_2.0.obj"/>
            </geometry>
            <material name="green"/>
        </visual>
        <collision>
            <!--<origin xyz="0 0 0.0" rpy="0 0 0" />
            <geometry>
                <mesh filename="../../../Model/meshes/collision/link_2.0.obj" scale="1 1 1" />
            </geometry> -->
        </collision>
    </link>
    
    <joint name="joint_10.0" type="revolute">
        <axis xyz="0 1 0"/>
        <limit effort="0" lower="-0.174" upper="1.709" velocity="0"/>
        <parent link="link_9.0"/>
        <child link="link_10.0"/>
        <origin xyz="0 0 0.054"/>
    </joint>
    
   <link name="link_11.0">
        <inertial>
            <mass value="0.0096" />
            <origin xyz="0 0 0" rpy="0 0 0"/>
            <inertia ixx="4.701248e-06" ixy="1.255968e-06" ixz="1.2936e-06"
                       iyy="3.649312e-06" iyz="1.7622e-06"
                       izz="4.701248e-06" />
        </inertial>
        <visual>
            <geometry>
                <mesh filename="../../../Model/AllegroHand/meshes/visual/link_3.0.obj"/>
            </geometry>
            <material name="green"/>
        </visual>
         <collision>        
        </collision> 
    </link>

    <joint name="joint_11.0" type="revolute">
        <axis xyz="0 1 0"/>
        <limit effort="0" lower="-0.227" upper="1.618" velocity="0"/>
        <parent link="link_10.0"/>
        <child link="link_11.0"/>
        <origin xyz="0 0 0.0384"/>
    </joint>


    <link name="link_11.0_tip">
        <inertial>
            <mass value="0.0096" />
            <origin xyz="0 0 0" rpy="0 0 0"/>
            <inertia ixx="4.701248e-06" ixy="1.255968e-06" ixz="1.2936e-06"
                       iyy="3.649312e-06" iyz="1.7622e-06"
                       izz="4.701248e-06" />
        </inertial>
        <visual>
            <origin xyz="0.0 0.0 0.0" rpy="0 0 0" />
            <geometry>
                <!-- <mesh filename="../../../Model/AllegroHand/meshes/visual/link_3.0_tip.obj"/> -->
                <sphere radius="0.014" />
            </geometry>
            <material name="green"/>
        </visual>
        <collision>
            <origin xyz="0 0 0.0" rpy="0 0 0" />
            <geometry>
                <!--<mesh filename="link_3.0_tip.obj" scale="1 1 1" />-->
                <sphere radius="0.014" />
            </geometry>            
        </collision>
    </link>

    <joint name="joint_11.0_tip" type="fixed">
        <parent link="link_11.0"/>
        <child link="link_11.0_tip"/>
        <origin rpy="0 0 0" xyz="0 0 0.0297"/> <!--The tip joint is in the center of the sphere, which is 0.0157+0.014 m from the joint_3.0-->
    </joint> 
    
     <!-- THUMB -->
    <link name="link_12.0">
        <inertial>
            <origin xyz="0.0 0.0 0.0" rpy="0 0 0" />
            <mass value="0.0176" />
            <inertia ixx="1.89273333333e-5" iyy="1.43008213333e-05" izz="1.89273333333e-05" ixy="7.16716e-06" ixz="5.35568e-06" iyz="6.8068e-06" />
        </inertial>
        <visual>
            <geometry>
                <mesh filename="../../../Model/AllegroHand/meshes/visual/link_12.0_right.obj"/>
            </geometry>
            <material name="green"/>
        </visual>
        <collision>
            <!--<origin xyz="0 0 0.0" rpy="0 0 0" />
            <geometry>
                <mesh filename="link_12.0_right.obj" scale="1 1 1" />
            </geometry> -->
        </collision> 
    </link>
    
    <joint name="joint_912.0" type="revolute">
        <axis xyz="1 0 0"/>
        <limit effort="0" lower="-1.396" upper="-0.263" velocity="0"/>
        <parent link="palm"/>
        <child link="link_12.0"/>
        <origin rpy="0 -1.65806278845 -1.5707963259" xyz="-0.0182 0.0193112 -0.046391"/> <!--"-0.0182 0.016958 -0.073288"-->
    </joint>
    
    <link name="link_13.0">
        <inertial>
            <origin xyz="0.0 0.0 0.0" rpy="0 0 0" />
            <mass value="0.0119" />
            <inertia ixx="4.24250866667e-06" iyy="4.52362633333e-06" izz="4.24250866667e-06" ixy="1.032087e-06" ixz="1.603525e-06" iyz="1.44808125e-06" />
        </inertial>
        <visual>
            <geometry>
                <mesh filename="../../../Model/AllegroHand/meshes/visual/link_13.0.obj"/>
            </geometry>
            <material name="green"/>
            </visual>
        <collision>
            <!--<origin xyz="0 0 0.0" rpy="0 0 0" />
            <geometry>
                <mesh filename="link_13.0.obj" scale="1 1 1" />
            </geometry> -->
        </collision>
    </link>
    
    <joint name="joint_913.0" type="revolute">
        <axis xyz="0 0 1"/>
        <limit effort="0" lower="-0.105" upper="1.163" velocity="0"/>
        <parent link="link_12.0"/>
        <child link="link_13.0"/>
        <!-- RIGHT -->
        <origin xyz="-0.027 0.005 0.0388"/>
        <!-- LEFT -->
        <!-- <origin xyz="-0.027 -0.005 0.0399"/> -->
    </joint>
    
    <link name="link_14.0">
        <inertial>
            <origin xyz="0.0 0.0 0.0" rpy="0 0 0" />
            <mass value="0.038" />
            <inertia ixx="4.30439933333e-05" iyy="1.44451933333e-05" izz="4.30439933333e-05" ixy="9.57068e-06" ixz="5.1205e-06" iyz="1.342825e-05" />
        </inertial>
        <visual>
            <geometry>
                <mesh filename="../../../Model/AllegroHand/meshes/visual/link_14.0.obj"/>
            </geometry>
            <material name="green"/>
        </visual>
        <collision>
            <!--<origin xyz="0 0 0.0" rpy="0 0 0" />
            <geometry>
                <mesh filename="link_14.0.obj" scale="1 1 1" />
            </geometry> -->
        </collision>
    </link>
    
    <joint name="joint_914.0" type="revolute">
        <axis xyz="0 1 0"/>
        <limit effort="0" lower="-0.189" upper="1.644" velocity="0"/>
        <parent link="link_13.0"/>
        <child link="link_14.0"/>
        <origin xyz="0 0 0.0166"/>
    </joint>


    
    <link name="link_15.0">
        <inertial>
            <origin xyz="0.0 0.0 0.0" rpy="0 0 0" />
            <mass value="0.0388" />
            <inertia ixx="3.29223173333e-05" iyy="1.47493026667e-5" izz="3.29223173333e-05" ixy="8.042076e-06" ixz="5.2283e-06" iyz="1.1283525e-5" />
        </inertial>
        <visual>
            <geometry>
                <mesh filename="../../../Model/AllegroHand/meshes/visual/link_15.0.obj"/>
            </geometry>
            <material name="green">
            </material>
        </visual>
        <collision>
        </collision>
    </link>

    <joint name="joint_915.0" type="revolute">
        <axis xyz="0 1 0"/>
        <limit effort="0" lower="-0.162" upper="1.719" velocity="0"/>
        <parent link="link_14.0"/>
        <child link="link_15.0"/>
        <origin xyz="0 0 0.0514"/>
    </joint>

    <link name="link_15.0_tip">
        <inertial>
          <mass value="0.0168"/>
          <origin rpy="0 0 0" xyz="0 0 0"/>
          <inertia ixx="9.68e-07" ixy="0" ixz="0" iyy="9.68e-07" iyz="0" izz="9.68e-07"/>
        </inertial>
        <visual>
            <origin xyz="0.0 0.0 0.0" rpy="0 0 0" />
            <geometry>
                <!-- <mesh filename="../../../Model/AllegroHand/meshes/visual/link_3.0_tip.obj"/> -->
                <sphere radius="0.014" />
            </geometry>
            <material name="green"/>
        </visual>
        <collision>
            <origin xyz="0 0 0.0" rpy="0 0 0" />
            <geometry>
                <!--<mesh filename="link_15.0.obj" scale="1 1 1" />-->
                <sphere radius="0.014"/>
            </geometry> 
        </collision>
    </link>

    <joint name="joint_15.0_tip" type="fixed">
        <parent link="link_15.0"/>
        <child link="link_15.0_tip"/>
        <origin rpy="0 0 0" xyz="0 0 0.0453"/> <!--31.3+14=45.3-->
    </joint>   


</robot>
