<?xml version='1.0' encoding='utf-8'?>
<robot name="pbot">

    <link name="link0">
      <inertial>
        <origin xyz="0 0 0.0" rpy="0 0 0" />
        <mass value="4" />
        <inertia ixx="0.4" iyy="0.4" izz="0.4" ixy="0" ixz="0" iyz="0" />
      </inertial>
    </link>
    <link name="link1">
      <inertial>
        <origin xyz="0 0 -0.0" rpy="0 -0 0" />
        <mass value="1" />
        <inertia ixx="0.3" iyy="0.3" izz="0.3" ixy="0" ixz="0" iyz="0" />
      </inertial>
      <visual>
        <geometry>
          <sphere radius="0.04"/>
        </geometry>
        <material name="material_blue">
          <color rgba="0.50 0.92 1.00 1.0" />
        </material>
      </visual>
      <collision>
        <geometry>
          <sphere radius="0.04"/>
        </geometry>
      </collision>
    </link>
   
    <joint name="joint1" type="prismatic">
      <safety_controller k_position="100.0" k_velocity="40.0" soft_lower_limit="-2.8973" soft_upper_limit="2.8973"/>
      <origin rpy="0 0 0" xyz="0 0 0.35"/>
      <parent link="link0"/>
      <child link="link1"/>
      <axis xyz="0 0 1"/>
      <limit effort="87" lower="-2.8973" upper="2.8973" velocity="2.1750"/>
    </joint>
</robot>
