<?xml version='1.0' encoding='utf-8'?>
<robot name="truck_panda">


    <link name="base">
      <inertial>
        <origin xyz="0 0 0" rpy="0 0 0" />
        <mass value="4" />
        <inertia ixx="0.4" iyy="0.4" izz="0.4" ixy="0" ixz="0" iyz="0" />
      </inertial>
    </link>
    
    <link name="truck_base">
      <inertial>
        <origin xyz="0 0 0" rpy="0 0 0" />
        <mass value="400" />
        <inertia ixx="40" iyy="40" izz="40" ixy="0" ixz="0" iyz="0" />
      </inertial>
      <visual>
        <geometry>
          <mesh filename="../../../Model/objects/Truck/truck_base.obj"/>
          <!-- <mesh filename="../../../Model/objects/Truck/cubes.obj"/> -->
        </geometry>
      </visual>
    </link>

    <link name="virtual_1">
      <inertial>
        <origin xyz="0 0 0" rpy="0 0 0" />
        <mass value="0.000001" />
        <inertia ixx="0.00001" iyy="0.00001" izz="0.00001" ixy="0" ixz="0" iyz="0" />
      </inertial>
    </link>

    <link name="first_bar">
      <inertial>
        <origin xyz="0 0 0" rpy="0 0 0" />
        <mass value="5" />
        <inertia ixx="1" iyy="1" izz="1" ixy="0" ixz="0" iyz="0" />
      </inertial>
      <visual>
        <origin xyz="0 -2.25 0" rpy="0 0 0" />
        <geometry>
          <box size="0.2 4.5 0.2"/>
        </geometry>
        <material name="material_bar">
          <color rgba="0.2 0.2 0.2 1.0" />
      </material>
      </visual>
      <visual>
        <origin xyz="-0.11 -4.5 0.15" rpy="0 1.57079632679 0" />
        <geometry>
          <cylinder radius="0.30" length="0.22"/>
        </geometry>
        <material name="material_bar">
          <color rgba="0.01 0.01 0.01 1.0" />
      </material>
      </visual>
    </link>

    <link name="second_bar">
      <inertial>
        <origin xyz="0 0 0" rpy="0 0 0" />
        <mass value="5" />
        <inertia ixx="1" iyy="1" izz="1" ixy="0" ixz="0" iyz="0" />
      </inertial>
      <visual>
        <origin xyz="0 2 0.1" rpy="0 0 0" />
        <geometry>
          <box size="0.2 4 0.2"/>
        </geometry>
        <material name="material_bar">
          <color rgba="0.2 0.2 0.2 1.0" />
      </material>
      </visual>
      <visual>
        <origin xyz="-0.11 4 0.3" rpy="0 1.57079632679 0" />
        <geometry>
          <cylinder radius="0.30" length="0.22"/>
        </geometry>
        <material name="material_bar">
          <color rgba="0.01 0.01 0.01 1.0" />
      </material>
      </visual>
    </link>

    <link name="virtual_bucket">
      <inertial>
        <origin xyz="0 0 0" rpy="0 0 0" />
        <mass value="0.0001" />
        <inertia ixx="0.0001" iyy="0.0001" izz="0.0001" ixy="0" ixz="0" iyz="0" />
      </inertial>
    </link>

    <link name="basket">
      <inertial>
        <origin xyz="0 0 0" rpy="0 0 0" />
        <mass value="5" />
        <inertia ixx="1" iyy="1" izz="1" ixy="0" ixz="0" iyz="0" />
      </inertial>
      <visual>
        <origin xyz="0 0 0.7" rpy="0 0 0" />
        <geometry>
          <box size="0.6 0.5 1.0"/>
        </geometry>
        <material name="material_basket">
          <color rgba="0.35 0.35 0.35 1.0" />
      </material>
      </visual>
    </link>

<!--   LEFT ARM     -->

    <link name="left_arm_link1">
      <inertial>
        <origin xyz="0 0 -0.07" rpy="0 -0 0" />
        <mass value="3" />
        <inertia ixx="0.3" iyy="0.3" izz="0.3" ixy="0" ixz="0" iyz="0" />
      </inertial>
      <visual>
        <geometry>
          <mesh filename="../../../Model/meshes/visual/link1.obj"/>
        </geometry>
      </visual>
    </link>
    <link name="left_arm_link2">
      <inertial>
        <origin xyz="0 -0.1 0" rpy="0 -0 0" />
        <mass value="3" />
        <inertia ixx="0.3" iyy="0.3" izz="0.3" ixy="0" ixz="0" iyz="0" />
      </inertial>
      <visual>
        <geometry>
          <mesh filename="../../../Model/meshes/visual/link2.obj"/>
        </geometry>
      </visual>
    </link>
    <link name="left_arm_link3">
      <inertial>
        <origin xyz="0.04 0 -0.05" rpy="0 -0 0" />
        <mass value="2" />
        <inertia ixx="0.2" iyy="0.2" izz="0.2" ixy="0" ixz="0" iyz="0" />
      </inertial>
      <visual>
        <geometry>
          <mesh filename="../../../Model/meshes/visual/link3.obj"/>
        </geometry>
      </visual>
    </link>
    <link name="left_arm_link4">
      <inertial>
        <origin xyz="-0.04 0.05 0" rpy="0 -0 0" />
        <mass value="2" />
        <inertia ixx="0.2" iyy="0.2" izz="0.2" ixy="0" ixz="0" iyz="0" />
      </inertial>
      <visual>
        <geometry>
          <mesh filename="../../../Model/meshes/visual/link4.obj"/>
        </geometry>
      </visual>
    </link>
    <link name="left_arm_link5">
      <inertial>
        <origin xyz="0 0 -0.15" rpy="0 -0 0" />
        <mass value="2" />
        <inertia ixx="0.2" iyy="0.2" izz="0.2" ixy="0" ixz="0" iyz="0" />
      </inertial>
      <visual>
        <geometry>
          <mesh filename="../../../Model/meshes/visual/link5.obj"/>
        </geometry>
      </visual>
    </link>
    <link name="left_arm_link6">
      <inertial>
        <origin xyz="0.06 0 0" rpy="0 -0 0" />
        <mass value="1.5" />
        <inertia ixx="0.1" iyy="0.1" izz="0.1" ixy="0" ixz="0" iyz="0" />
      </inertial>
      <visual>
        <geometry>
          <mesh filename="../../../Model/meshes/visual/link6.obj"/>
        </geometry>
      </visual>
    </link>
    <link name="left_arm_link7">
      <inertial>
        <origin xyz="0 0 0.17" rpy="0 -0 0" />
        <mass value="1.8" />
        <inertia ixx="0.09" iyy="0.05" izz="0.07" ixy="0" ixz="0" iyz="0" />
      </inertial>
      <visual>
        <geometry>
          <mesh filename="../../../Model/meshes/visual/link7.obj"/>
        </geometry>
      </visual>
    </link>

<!--   RIGHT ARM     -->

    <link name="right_arm_link1">
      <inertial>
        <origin xyz="0 0 -0.07" rpy="0 -0 0" />
        <mass value="3" />
        <inertia ixx="0.3" iyy="0.3" izz="0.3" ixy="0" ixz="0" iyz="0" />
      </inertial>
      <visual>
        <geometry>
          <mesh filename="../../../Model/meshes/visual/link1.obj"/>
        </geometry>
      </visual>
    </link>
    <link name="right_arm_link2">
      <inertial>
        <origin xyz="0 -0.1 0" rpy="0 -0 0" />
        <mass value="3" />
        <inertia ixx="0.3" iyy="0.3" izz="0.3" ixy="0" ixz="0" iyz="0" />
      </inertial>
      <visual>
        <geometry>
          <mesh filename="../../../Model/meshes/visual/link2.obj"/>
        </geometry>
      </visual>
    </link>
    <link name="right_arm_link3">
      <inertial>
        <origin xyz="0.04 0 -0.05" rpy="0 -0 0" />
        <mass value="2" />
        <inertia ixx="0.2" iyy="0.2" izz="0.2" ixy="0" ixz="0" iyz="0" />
      </inertial>
      <visual>
        <geometry>
          <mesh filename="../../../Model/meshes/visual/link3.obj"/>
        </geometry>
      </visual>
    </link>
    <link name="right_arm_link4">
      <inertial>
        <origin xyz="-0.04 0.05 0" rpy="0 -0 0" />
        <mass value="2" />
        <inertia ixx="0.2" iyy="0.2" izz="0.2" ixy="0" ixz="0" iyz="0" />
      </inertial>
      <visual>
        <geometry>
          <mesh filename="../../../Model/meshes/visual/link4.obj"/>
        </geometry>
      </visual>
    </link>
    <link name="right_arm_link5">
      <inertial>
        <origin xyz="0 0 -0.15" rpy="0 -0 0" />
        <mass value="2" />
        <inertia ixx="0.2" iyy="0.2" izz="0.2" ixy="0" ixz="0" iyz="0" />
      </inertial>
      <visual>
        <geometry>
          <mesh filename="../../../Model/meshes/visual/link5.obj"/>
        </geometry>
      </visual>
    </link>
    <link name="right_arm_link6">
      <inertial>
        <origin xyz="0.06 0 0" rpy="0 -0 0" />
        <mass value="1.5" />
        <inertia ixx="0.1" iyy="0.1" izz="0.1" ixy="0" ixz="0" iyz="0" />
      </inertial>
      <visual>
        <geometry>
          <mesh filename="../../../Model/meshes/visual/link6.obj"/>
        </geometry>
      </visual>
    </link>
    <link name="right_arm_link7">
      <inertial>
        <origin xyz="0 0 0.17" rpy="0 -0 0" />
        <mass value="1.8" />
        <inertia ixx="0.09" iyy="0.05" izz="0.07" ixy="0" ixz="0" iyz="0" />
      </inertial>
      <visual>
        <geometry>
          <mesh filename="../../../Model/meshes/visual/link7.obj"/>
        </geometry>
      </visual>
    </link>


<!--    JOINTS     -->
    <joint name="driving" type="prismatic">
      <safety_controller k_position="100.0" k_velocity="40.0" soft_lower_limit="-2.8973" soft_upper_limit="2.8973"/>
      <origin rpy="0 0 0" xyz="0 0 0"/>
      <parent link="base"/>
      <child link="truck_base"/>
      <axis xyz="0 1 0"/>
      <calibration rising="10" />
      <limit effort="87" lower="-2.8973" upper="2.8973" velocity="2.1750"/>
    </joint>

    <joint name="r1_truck" type="revolute">
      <origin rpy="0 0 0" xyz="2.85 6.35 2.4"/>
      <parent link="truck_base"/>
      <child link="virtual_1"/>
      <axis xyz="0 0 1"/>
      <limit effort="87" lower="-2.8973" upper="2.8973" velocity="2.1750"/>
    </joint>

    <joint name="r2_truck" type="revolute">
      <origin rpy="0 0 0" xyz="0 0 0"/>
      <parent link="virtual_1"/>
      <child link="first_bar"/>
      <axis xyz="1 0 0"/>
      <calibration falling="-5.0" />
      <limit effort="87" lower="-2.8973" upper="2.8973" velocity="2.1750"/>
    </joint>

    <joint name="r3_truck" type="revolute">
      <origin rpy="0 0 0" xyz="0 -4.5 0.15"/>
      <parent link="first_bar"/>
      <child link="second_bar"/>
      <axis xyz="1 0 0"/>
      <!-- <calibration falling="5.0" /> -->
      <limit effort="87" lower="-2.8973" upper="2.8973" velocity="2.1750"/>
    </joint>

    <joint name="r4_truck" type="revolute">
      <origin rpy="0 0 0" xyz="0 4 0.3"/>
      <parent link="second_bar"/>
      <child link="virtual_bucket"/>
      <axis xyz="1 0 0"/>
      <calibration falling="5.0" />
      <limit effort="87" lower="-2.8973" upper="2.8973" velocity="2.1750"/>
    </joint>

    <joint name="r5_truck" type="revolute">
      <origin rpy="0 0 0" xyz="0 0 0"/>
      <parent link="virtual_bucket"/>
      <child link="basket"/>
      <axis xyz="0 0 1"/>
      <calibration falling="5.0" />
      <limit effort="87" lower="-2.8973" upper="2.8973" velocity="2.1750"/>
    </joint>

<!--   LEFT ARM JOINT     -->

    <joint name="left_arm_joint1" type="revolute">
      <safety_controller k_position="100.0" k_velocity="40.0" soft_lower_limit="-2.8973" soft_upper_limit="2.8973"/>
      <origin rpy="-1.57079632679 0 -1.57079632679" xyz="0.5 0.0 0.9"/>
      <parent link="basket"/>
      <child link="left_arm_link1"/>
      <axis xyz="0 0 1"/>
      <limit effort="87" lower="-2.8973" upper="2.8973" velocity="2.1750"/>
    </joint>
    <joint name="left_arm_joint2" type="revolute">
      <safety_controller k_position="100.0" k_velocity="40.0" soft_lower_limit="-1.7628" soft_upper_limit="1.7628"/>
      <origin rpy="-1.57079632679 0 0" xyz="0 0 0"/>
      <parent link="left_arm_link1"/>
      <child link="left_arm_link2"/>
      <axis xyz="0 0 1"/>
      <calibration falling="15.0" />
      <limit effort="87" lower="-1.7628" upper="1.7628" velocity="2.1750"/>
    </joint>
    <joint name="left_arm_joint3" type="revolute">
      <safety_controller k_position="100.0" k_velocity="40.0" soft_lower_limit="-2.8973" soft_upper_limit="2.8973"/>
      <origin rpy="1.57079632679 0 0" xyz="0 -0.316 0"/>
      <parent link="left_arm_link2"/>
      <child link="left_arm_link3"/>
      <axis xyz="0 0 1"/>
      <limit effort="87" lower="-2.8973" upper="2.8973" velocity="2.1750"/>
    </joint>
    <joint name="left_arm_joint4" type="revolute">
      <safety_controller k_position="100.0" k_velocity="40.0" soft_lower_limit="-3.0718" soft_upper_limit="-0.0698"/>
      <origin rpy="1.57079632679 0 0" xyz="0.0825 0 0"/>
      <parent link="left_arm_link3"/>
      <child link="left_arm_link4"/>
      <axis xyz="0 0 1"/>
      <calibration falling="-95.0" />
      <limit effort="87" lower="-3.0718" upper="-0.0698" velocity="2.1750"/>
    </joint>
    <joint name="left_arm_joint5" type="revolute">
      <safety_controller k_position="100.0" k_velocity="40.0" soft_lower_limit="-2.8973" soft_upper_limit="2.8973"/>
      <origin rpy="-1.57079632679 0 0" xyz="-0.0825 0.384 0"/>
      <parent link="left_arm_link4"/>
      <child link="left_arm_link5"/>
      <axis xyz="0 0 1"/>
      <limit effort="12" lower="-2.8973" upper="2.8973" velocity="2.6100"/>
    </joint>
    <joint name="left_arm_joint6" type="revolute">
      <safety_controller k_position="100.0" k_velocity="40.0" soft_lower_limit="-0.0175" soft_upper_limit="3.7525"/>
      <origin rpy="1.57079632679 0 0" xyz="0 0 0"/>
      <parent link="left_arm_link5"/>
      <child link="left_arm_link6"/>
      <axis xyz="0 0 1"/>
      <calibration falling="125.0" />
      <limit effort="12" lower="-0.0175" upper="3.7525" velocity="2.6100"/>
    </joint>
    <joint name="left_arm_joint7" type="revolute">
      <safety_controller k_position="100.0" k_velocity="40.0" soft_lower_limit="-2.8973" soft_upper_limit="2.8973"/>
      <origin rpy="1.57079632679 0 0" xyz="0.088 0 0"/>
      <parent link="left_arm_link6"/>
      <child link="left_arm_link7"/>
      <axis xyz="0 0 1"/>
      <limit effort="12" lower="-2.8973" upper="2.8973" velocity="2.6100"/>
    </joint>

<!--   RIGHT ARM JOINT     -->

    <joint name="right_arm_joint1" type="revolute">
      <safety_controller k_position="100.0" k_velocity="40.0" soft_lower_limit="-2.8973" soft_upper_limit="2.8973"/>
      <origin rpy="1.57079632679 0 -1.57079632679" xyz="-0.5 0.0 0.9"/>
      <parent link="basket"/>
      <child link="right_arm_link1"/>
      <axis xyz="0 0 1"/>
      <limit effort="87" lower="-2.8973" upper="2.8973" velocity="2.1750"/>
    </joint>
    <joint name="right_arm_joint2" type="revolute">
      <safety_controller k_position="100.0" k_velocity="40.0" soft_lower_limit="-1.7628" soft_upper_limit="1.7628"/>
      <origin rpy="-1.57079632679 0 0" xyz="0 0 0"/>
      <parent link="right_arm_link1"/>
      <child link="right_arm_link2"/>
      <axis xyz="0 0 1"/>
      <calibration falling="15.0" />
      <limit effort="87" lower="-1.7628" upper="1.7628" velocity="2.1750"/>
    </joint>
    <joint name="right_arm_joint3" type="revolute">
      <safety_controller k_position="100.0" k_velocity="40.0" soft_lower_limit="-2.8973" soft_upper_limit="2.8973"/>
      <origin rpy="1.57079632679 0 0" xyz="0 -0.316 0"/>
      <parent link="right_arm_link2"/>
      <child link="right_arm_link3"/>
      <axis xyz="0 0 1"/>
      <limit effort="87" lower="-2.8973" upper="2.8973" velocity="2.1750"/>
    </joint>
    <joint name="right_arm_joint4" type="revolute">
      <safety_controller k_position="100.0" k_velocity="40.0" soft_lower_limit="-3.0718" soft_upper_limit="-0.0698"/>
      <origin rpy="1.57079632679 0 0" xyz="0.0825 0 0"/>
      <parent link="right_arm_link3"/>
      <child link="right_arm_link4"/>
      <axis xyz="0 0 1"/>
      <calibration falling="-95.0" />
      <limit effort="87" lower="-3.0718" upper="-0.0698" velocity="2.1750"/>
    </joint>
    <joint name="right_arm_joint5" type="revolute">
      <safety_controller k_position="100.0" k_velocity="40.0" soft_lower_limit="-2.8973" soft_upper_limit="2.8973"/>
      <origin rpy="-1.57079632679 0 0" xyz="-0.0825 0.384 0"/>
      <parent link="right_arm_link4"/>
      <child link="right_arm_link5"/>
      <axis xyz="0 0 1"/>
      <limit effort="12" lower="-2.8973" upper="2.8973" velocity="2.6100"/>
    </joint>
    <joint name="right_arm_joint6" type="revolute">
      <safety_controller k_position="100.0" k_velocity="40.0" soft_lower_limit="-0.0175" soft_upper_limit="3.7525"/>
      <origin rpy="1.57079632679 0 0" xyz="0 0 0"/>
      <parent link="right_arm_link5"/>
      <child link="right_arm_link6"/>
      <axis xyz="0 0 1"/>
      <calibration falling="125.0" />
      <limit effort="12" lower="-0.0175" upper="3.7525" velocity="2.6100"/>
    </joint>
    <joint name="right_arm_joint7" type="revolute">
      <safety_controller k_position="100.0" k_velocity="40.0" soft_lower_limit="-2.8973" soft_upper_limit="2.8973"/>
      <origin rpy="1.57079632679 0 0" xyz="0.088 0 0"/>
      <parent link="right_arm_link6"/>
      <child link="right_arm_link7"/>
      <axis xyz="0 0 1"/>
      <limit effort="12" lower="-2.8973" upper="2.8973" velocity="2.6100"/>
    </joint>


</robot>
